Workbook
Name A: 'Cost Until 07-26'!$F$7
Name B: 'Cost Until 07-26'!$C:$D

Sheet Sum_detailed
B2: EPC | C2: 100 | D2: =SUM(Budget!F2:F22) -> 0 | E2: =SUM(Budget!G2:G22) -> 509.6 | F2: =SUM(Budget!H2:H22) -> 30509.6 | G2: =SUM(Budget!I2:I22) -> 25742.817 | H2: =SUM(Budget!J2:J22) -> 509.6 | I2: =SUM(Budget!K2:K22) -> 36384.257 | J2: =SUM(Budget!L2:L22) -> 20767.896 | K2: =SUM(Budget!M2:M22) -> 9937.2194 | ... KI2: =SUM(Budget!KK2:KK22) -> 0
B3: Advance Payment | C3: 101
B4: PID | C4: 102
B5: ITS | C5: 103
B6: Contruction Toll Plaza | C6: 104
B7: EPC Others | C7: 105
B8: Expropriation & Land Acquisition | C8: 106
B9: Utility Relocation | C9: 107
B10: Citizen & Enviromental Studies | C10: 108
B11: EPC Works | C11: 109
B12: Construction Department Others | C12: 110
B13: MAINTENANCE | C13: 200 | D13: =SUM(Budget!F23:F35) -> 2301.1395 | E13: =SUM(Budget!G23:G35) -> 11526.102 | F13: =SUM(Budget!H23:H35) -> 11749.198 | G13: =SUM(Budget!I23:I35) -> 12556.52 | H13: =SUM(Budget!J23:J35) -> 16696.956 | I13: =SUM(Budget!K23:K35) -> 14984.371 | J13: =SUM(Budget!L23:L35) -> 11818.264 | K13: =SUM(Budget!M23:M35) -> 11633.837 | ... KI13: =SUM(Budget!KK23:KK35) -> 0
B14: Routine Maintenance | C14: 201
B15: Major Maintenances | C15: 202
B16: RM-MM | C16: 203
B17: Maintenance Studies | C17: 204
B18: Maintenance Others Works | C18: 205
B19: Maintenance ASG-Toll Plaza | C19: 206
B20: OPERATIONS | C20: 300 | D20: =SUM(Budget!F36:F42) -> 47139 | E20: =SUM(Budget!G36:G42) -> 17169.422 | F20: =SUM(Budget!H36:H42) -> 17890.711 | G20: =SUM(Budget!I36:I42) -> 16737.939 | H20: =SUM(Budget!J36:J42) -> 19869.528 | I20: =SUM(Budget!K36:K42) -> 20009.026 | J20: =SUM(Budget!L36:L42) -> 23938.713 | K20: =SUM(Budget!M36:M42) -> 19341.088 | ... KI20: =SUM(Budget!KK36:KK42) -> 0
B21: Operations | C21: 301
B22: Backoffice | C22: 302
B23: SPV | C23: 400 | D23: =SUM(Budget!F43:F48) -> 3639.9695 | E23: =SUM(Budget!G43:G48) -> 5932.2995 | F23: =SUM(Budget!H43:H48) -> 6093.9695 | G23: =SUM(Budget!I43:I48) -> 5479.2895 | H23: =SUM(Budget!J43:J48) -> 26444.96 | I23: =SUM(Budget!K43:K48) -> 9851.4395 | J23: =SUM(Budget!L43:L48) -> 10184.46 | K23: =SUM(Budget!M43:M48) -> 10989.8 | ... KI23: =SUM(Budget!KK43:KK48) -> 0
B24: Administration Department | C24: 401
B25: Others | C25: 402
B26: Legal Department | C26: 403
B27: HR Department | C27: 404
B28: Finance Department | C28: 405
B29: Economic Department | C29: 406
B30: Utilities | C30: 407
B31: IGYC Costs | C31: 408
B32: MOP | C32: 500
B33: Revenue Sharing | C33: 501
B34: Contract Management Fees | C34: 502
B35: Franchise Fees | C35: 503
... B41: Other Financing Fees | C41: 603
B42: INSURANCE & GUARANTEE | C42: 700 | D42: =SUM(Budget!F49:F50) -> 3242.5833 | E42: =SUM(Budget!G49:G50) -> 3242.5833 | F42: =SUM(Budget!H49:H50) -> 3242.5833 | G42: =SUM(Budget!I49:I50) -> 3242.5833 | H42: =SUM(Budget!J49:J50) -> 3242.5833 | I42: =SUM(Budget!K49:K50) -> 3242.5833 | J42: =SUM(Budget!L49:L50) -> 3242.5833 | K42: =SUM(Budget!M49:M50) -> 3242.5833 | ... KI42: =SUM(Budget!KK49:KK50) -> 0
B43: Insurance | C43: 701
B44: Guarantee | C44: 702
B45: TAX | C45: 800
B46: VAT | C46: 801
...

Sheet Summary
E3: UNTIL JULY 2026
C4: ITEM | D4: CATEGORY | E4: BUDGET | F4: COST
C5: EPC | D5: 100 | E5: =Balance!D2 -> 2748292.4 | F5: =Balance!D10 -> 2655427.5
C6: ROUTINE MAINTENANCE | D6: 201 | E6: =Balance!D3 -> 606587.55 | F6: =Balance!D11 -> 576929
C7: MAJOR MAINTENANCE | D7: 202 | E7: =Balance!D4 -> 1020526.4 | F7: =Balance!D12 -> 1043357.8
C8: OPERATIONS | D8: 300 | E8: =Balance!D5 -> 1858373.1 | F8: =Balance!D13 -> 1808099.6
C9: SPV | D9: 400 | E9: =Balance!D6 -> 862102.27 | F9: =Balance!D14 -> 625741.07
C10: MOP | D10: 500 | E10: =Balance!D7 -> 8357719.8 | F10: =Balance!D15+Balance!D16+Balance!D17 -> 6377940
C11: INSURANCE & GUARANTEE | D11: 700 | E11: =Balance!D8 -> 206091.06 | F11: =Balance!D18 -> 202513
C12: TAX | D12: 800 | E12: =Balance!D9 -> 129962.5 | F12: =Balance!D19 -> 54110.842
D13: TOTAL | E13: =SUM(E5:E12) -> 15789655 | F13: =SUM(F5:F12) -> 13344119
C15: * June 2026 cost is based on estimates

Sheet Balance
B1: ITEM | C1: CATEGORY | D1: JULY 2026 | E1: =Budget!F1 -> 44287 | F1: =Budget!G1 -> 44317 | G1: =Budget!H1 -> 44348 | H1: =Budget!I1 -> 44378 | I1: =Budget!J1 -> 44409 | J1: =Budget!K1 -> 44440 | K1: =Budget!L1 -> 44470 | L1: =Budget!M1 -> 44501 | ... KG1: =Budget!KH1 -> 53053
A2: BUDGET | B2: EPC | C2: 100 | D2: =SUM(E2:BP2) -> 2748292.4 | E2: =SUM(Budget!F2:F22) -> 0 | F2: =SUM(Budget!G2:G22) -> 509.6 | G2: =SUM(Budget!H2:H22) -> 30509.6 | H2: =SUM(Budget!I2:I22) -> 25742.817 | I2: =SUM(Budget!J2:J22) -> 509.6 | J2: =SUM(Budget!K2:K22) -> 36384.257 | K2: =SUM(Budget!L2:L22) -> 20767.896 | L2: =SUM(Budget!M2:M22) -> 9937.2194 | ... KG2: =SUM(Budget!KH2:KH22) -> 0
B3: ROUTINE MAINTENANCE | C3: 200 | D3: =SUM(E3:BP3) -> 606587.55 | E3: =SUM(Budget!F29:F34) -> 0 | F3: =SUM(Budget!G29:G34) -> 8500 | G3: =SUM(Budget!H29:H34) -> 8500 | H3: =SUM(Budget!I29:I34) -> 8500 | I3: =SUM(Budget!J29:J34) -> 8500 | J3: =SUM(Budget!K29:K34) -> 10751.164 | K3: =SUM(Budget!L29:L34) -> 8500 | L3: =SUM(Budget!M29:M34) -> 8500 | ... KG3: =SUM(Budget!KH29:KH34) -> 10000
B4: MAJOR MAINTENANCE | C4: 200 | D4: =SUM(E4:BP4) -> 1020526.4 | E4: =SUM(Budget!F23:F28) -> 0 | F4: =SUM(Budget!G23:G28) -> 0 | G4: =SUM(Budget!H23:H28) -> 0 | H4: =SUM(Budget!I23:I28) -> 0 | I4: =SUM(Budget!J23:J28) -> 0 | J4: =SUM(Budget!K23:K28) -> 0 | K4: =SUM(Budget!L23:L28) -> 0 | L4: =SUM(Budget!M23:M28) -> 0 | ... KG4: =SUM(Budget!KH23:KH28) -> 10000
B5: OPERATIONS | C5: 300 | D5: =SUM(E5:BP5) -> 1858373.1 | E5: =SUM(Budget!F35:F42) -> 49440.14 | F5: =SUM(Budget!G35:G42) -> 20195.524 | G5: =SUM(Budget!H35:H42) -> 21139.909 | H5: =SUM(Budget!I35:I42) -> 20794.459 | I5: =SUM(Budget!J35:J42) -> 28066.484 | J5: =SUM(Budget!K35:K42) -> 24242.233 | K5: =SUM(Budget!L35:L42) -> 27256.977 | L5: =SUM(Budget!M35:M42) -> 22474.925 | ... KG5: =SUM(Budget!KH35:KH42) -> 24152.58
B6: SPV | C6: 400 | D6: =SUM(E6:BP6) -> 862102.27 | E6: =SUM(Budget!F43:F48)+Budget!F53 -> 4435.7627 | F6: =SUM(Budget!G43:G48)+Budget!G53 -> 6728.0927 | G6: =SUM(Budget!H43:H48)+Budget!H53 -> 6889.7627 | H6: =SUM(Budget!I43:I48)+Budget!I53 -> 6275.0827 | I6: =SUM(Budget!J43:J48)+Budget!J53 -> 27240.753 | J6: =SUM(Budget!K43:K48)+Budget!K53 -> 10647.233 | K6: =SUM(Budget!L43:L48)+Budget!L53 -> 10980.253 | L6: =SUM(Budget!M43:M48)+Budget!M53 -> 11785.593 | ... KG6: =SUM(Budget!KH43:KH48)+Budget!KH53 -> 0
B7: MOP | C7: 500 | D7: =SUM(E7:BP7) -> 8357719.8 | E7: =Budget!F51 -> 18947.456 | F7: =Budget!G51 -> 18947.456 | G7: =Budget!H51 -> 18947.456 | H7: =Budget!I51 -> 18947.456 | I7: =Budget!J51 -> 18947.456 | J7: =Budget!K51 -> 18947.456 | K7: =Budget!L51 -> 18947.456 | L7: =Budget!M51 -> 18947.456 | ... KG7: =Budget!KH51 -> 0
B8: INSURANCE & GUARANTEE | C8: 700 | D8: =SUM(E8:BP8) -> 206091.06 | E8: =SUM(Budget!F49:F50) -> 3242.5833 | F8: =SUM(Budget!G49:G50) -> 3242.5833 | G8: =SUM(Budget!H49:H50) -> 3242.5833 | H8: =SUM(Budget!I49:I50) -> 3242.5833 | I8: =SUM(Budget!J49:J50) -> 3242.5833 | J8: =SUM(Budget!K49:K50) -> 3242.5833 | K8: =SUM(Budget!L49:L50) -> 3242.5833 | L8: =SUM(Budget!M49:M50) -> 3242.5833 | ... KG8: =SUM(Budget!KH49:KH50) -> 0
B9: TAX | C9: 800 | D9: =SUM(E9:BP9) -> 129962.5 | E9: =Budget!F52 -> 5981.9924 | F9: =Budget!G52 -> 0 | G9: =Budget!H52 -> 0 | H9: =Budget!I52 -> 0 | I9: =Budget!J52 -> 0 | J9: =Budget!K52 -> 0 | K9: =Budget!L52 -> 0 | L9: =Budget!M52 -> 0 | ... KG9: =Budget!KH52 -> 0
A10: COST | B10: EPC | C10: 100 | D10: =SUM(E10:BP10) -> 2655427.5 | E10: ='Cost Until 07-26'!G2+'Cost Until 07-26'!G31 -> 0 | F10: ='Cost Until 07-26'!H2+'Cost Until 07-26'!H31 -> 34620 | G10: ='Cost Until 07-26'!I2+'Cost Until 07-26'!I31 -> 1801 | H10: ='Cost Until 07-26'!J2+'Cost Until 07-26'!J31 -> 10517 | I10: ='Cost Until 07-26'!K2+'Cost Until 07-26'!K31 -> 27584 | J10: ='Cost Until 07-26'!L2+'Cost Until 07-26'!L31 -> 19328 | K10: ='Cost Until 07-26'!M2+'Cost Until 07-26'!M31 -> 13171 | L10: ='Cost Until 07-26'!N2+'Cost Until 07-26'!N31 -> 6523 | ... KG10: ='Cost Until 07-26'!KI2+'Cost Until 07-26'!KI31 -> 0
B11: ROUTINE MAINTENANCE | C11: 200 | D11: =SUM(E11:BP11) -> 576929 | E11: =SUM('Cost Until 07-26'!G48:G50) -> 0 | F11: =SUM('Cost Until 07-26'!H48:H50) -> 1498 | G11: =SUM('Cost Until 07-26'!I48:I50) -> 261 | H11: =SUM('Cost Until 07-26'!J48:J50) -> 105 | I11: =SUM('Cost Until 07-26'!K48:K50) -> 69 | J11: =SUM('Cost Until 07-26'!L48:L50) -> 492 | K11: =SUM('Cost Until 07-26'!M48:M50) -> 45901 | L11: =SUM('Cost Until 07-26'!N48:N50) -> 25500 | ... KG11: =SUM('Cost Until 07-26'!KI48:KI50) -> 0
B12: MAJOR MAINTENANCE | C12: 200 | D12: =SUM(E12:BP12) -> 1043357.8 | E12: =SUM('Cost Until 07-26'!G51:G61) -> 0 | F12: =SUM('Cost Until 07-26'!H51:H61) -> 0 | G12: =SUM('Cost Until 07-26'!I51:I61) -> 0 | H12: =SUM('Cost Until 07-26'!J51:J61) -> 0 | I12: =SUM('Cost Until 07-26'!K51:K61) -> 0 | J12: =SUM('Cost Until 07-26'!L51:L61) -> 1106 | K12: =SUM('Cost Until 07-26'!M51:M61) -> 1156 | L12: =SUM('Cost Until 07-26'!N51:N61) -> 0 | ... AZ12: =SUM('Cost Until 07-26'!BB51:BB61) -> 88747 | BA12: =SUM('Cost Until 07-26'!BC51:BC58)+SUM('Cost Until 07-26'!BC60:BC61) -> 15299 | BB12: =SUM('Cost Until 07-26'!BD51:BD58)+SUM('Cost Until 07-26'!BD60:BD61) -> 10998 | BC12: =SUM('Cost Until 07-26'!BE51:BE58)+SUM('Cost Until 07-26'!BE60:BE61) -> 22188.525 | BD12: =SUM('Cost Until 07-26'!BF51:BF58)+SUM('Cost Until 07-26'!BF60:BF61) -> 105.45456 | BE12: =SUM('Cost Until 07-26'!BG51:BG58)+SUM('Cost Until 07-26'!BG60:BG61) -> 49768.974 | BF12: =SUM('Cost Until 07-26'!BH51:BH58)+SUM('Cost Until 07-26'!BH60:BH61) -> 115.97354 | BG12: =SUM('Cost Until 07-26'!BI51:BI58)+SUM('Cost Until 07-26'!BI60:BI61) -> 48428.974 | BH12: =SUM('Cost Until 07-26'!BJ51:BJ58)+SUM('Cost Until 07-26'!BJ60:BJ61) -> 49131.67 | ... BM12: =SUM('Cost Until 07-26'!BO51:BO58)+SUM('Cost Until 07-26'!BO60:BO61) -> 106.94995 | BN12: =SUM('Cost Until 07-26'!BP51:BP61) -> 106.90117 | BO12: =SUM('Cost Until 07-26'!BQ51:BQ61) -> 1120.5312 | BP12: =SUM('Cost Until 07-26'!BR51:BR61) -> 14837.194 | BQ12: =SUM('Cost Until 07-26'!BS51:BS61) -> 0 | BR12: =SUM('Cost Until 07-26'!BT51:BT61) -> 0 | BS12: =SUM('Cost Until 07-26'!BU51:BU61) -> 0 | BT12: =SUM('Cost Until 07-26'!BV51:BV61) -> 0 | BU12: =SUM('Cost Until 07-26'!BW51:BW61) -> 0 | ... KG12: =SUM('Cost Until 07-26'!KI51:KI61) -> 0
B13: OPERATIONS | C13: 300 | D13: =SUM(E13:BP13) -> 1808099.6 | E13: ='Cost Until 07-26'!G62 -> 31312 | F13: ='Cost Until 07-26'!H62 -> 17724 | G13: ='Cost Until 07-26'!I62 -> 16577 | H13: ='Cost Until 07-26'!J62 -> 17453 | I13: ='Cost Until 07-26'!K62 -> 21441 | J13: ='Cost Until 07-26'!L62 -> 32810 | K13: ='Cost Until 07-26'!M62 -> 21600 | L13: ='Cost Until 07-26'!N62 -> 20279 | ... KG13: ='Cost Until 07-26'!KI62 -> 0
B14: SPV | C14: 400 | D14: =SUM(E14:BP14) -> 625741.07 | E14: ='Cost Until 07-26'!G129 -> 760 | F14: ='Cost Until 07-26'!H129 -> 5027 | G14: ='Cost Until 07-26'!I129 -> 4700 | H14: ='Cost Until 07-26'!J129 -> 3416 | I14: ='Cost Until 07-26'!K129 -> 15672 | J14: ='Cost Until 07-26'!L129 -> 3729 | K14: ='Cost Until 07-26'!M129 -> 11017 | L14: ='Cost Until 07-26'!N129 -> 7959 | ... KG14: ='Cost Until 07-26'!KI129 -> 0
B15: MOP - GOODS & RIGHTS | C15: 501 | D15: =SUM(E15:BP15) -> 2232000 | E15: ='Cost Until 07-26'!G44 -> 0 | F15: ='Cost Until 07-26'!H44 -> 0 | G15: ='Cost Until 07-26'!I44 -> 0 | H15: ='Cost Until 07-26'!J44 -> 0 | I15: ='Cost Until 07-26'!K44 -> 0 | J15: ='Cost Until 07-26'!L44 -> 0 | K15: ='Cost Until 07-26'!M44 -> 0 | L15: ='Cost Until 07-26'!N44 -> 0 | ... BP15: ='Cost Until 07-26'!BR44 -> 0
B16: MOP - PRE-EXISTING INFRASTRUCTURE | C16: 502 | D16: =SUM(E16:BP16) -> 3001047 | E16: ='Cost Until 07-26'!G45 -> 0 | F16: ='Cost Until 07-26'!H45 -> 0 | G16: ='Cost Until 07-26'!I45 -> 0 | H16: ='Cost Until 07-26'!J45 -> 0 | I16: ='Cost Until 07-26'!K45 -> 0 | J16: ='Cost Until 07-26'!L45 -> 0 | K16: ='Cost Until 07-26'!M45 -> 0 | L16: ='Cost Until 07-26'!N45 -> 0 | ... BP16: ='Cost Until 07-26'!BR45 -> 0
B17: MOP - TOLL REVENUE SHARING | C17: 503 | D17: =SUM(E17:BP17) -> 1144893 | E17: ='Cost Until 07-26'!G46 -> 0 | F17: ='Cost Until 07-26'!H46 -> 16284.864 | G17: ='Cost Until 07-26'!I46 -> 18467.727 | H17: ='Cost Until 07-26'!J46 -> 18410.304 | I17: ='Cost Until 07-26'!K46 -> 23018.454 | J17: ='Cost Until 07-26'!L46 -> 21517.786 | K17: ='Cost Until 07-26'!M46 -> 21810.214 | L17: ='Cost Until 07-26'!N46 -> 21749.376 | ... BP17: ='Cost Until 07-26'!BR46 -> 17486.47 | BQ17: ='Cost Until 07-26'!BS43 -> 0 | BR17: ='Cost Until 07-26'!BT43 -> 0 | BS17: ='Cost Until 07-26'!BU43 -> 0 | BT17: ='Cost Until 07-26'!BV43 -> 0 | BU17: ='Cost Until 07-26'!BW43 -> 0 | BV17: ='Cost Until 07-26'!BX43 -> 0 | BW17: ='Cost Until 07-26'!BY43 -> 0 | BX17: ='Cost Until 07-26'!BZ43 -> 0 | ... KG17: ='Cost Until 07-26'!KI43 -> 0
B18: INSURANCE & GUARANTEE | C18: 700 | D18: =SUM(E18:BP18) -> 202513 | E18: ='Cost Until 07-26'!G35 -> 948 | F18: ='Cost Until 07-26'!H35 -> 25300 | G18: ='Cost Until 07-26'!I35 -> 7582 | H18: ='Cost Until 07-26'!J35 -> 2 | I18: ='Cost Until 07-26'!K35 -> 0 | J18: ='Cost Until 07-26'!L35 -> 0 | K18: ='Cost Until 07-26'!M35 -> 0 | L18: ='Cost Until 07-26'!N35 -> 0 | ... KG18: ='Cost Until 07-26'!KI35 -> 0
B19: TAX | C19: 800 | D19: =SUM(E19:BP19) -> 54110.842 | E19: ='Cost Until 07-26'!G597 -> 0 | F19: ='Cost Until 07-26'!H597 -> 84 | G19: ='Cost Until 07-26'!I597 -> 1439 | H19: ='Cost Until 07-26'!J597 -> 589 | I19: ='Cost Until 07-26'!K597 -> 7463 | J19: ='Cost Until 07-26'!L597 -> 7620 | K19: ='Cost Until 07-26'!M597 -> 4802 | L19: ='Cost Until 07-26'!N597 -> 732 | ... KG19: ='Cost Until 07-26'!KI597 -> 0
D21: JULY 2026 | E21: =E1 -> 44287 | F21: =F1 -> 44317 | G21: =G1 -> 44348 | H21: =H1 -> 44378 | I21: =I1 -> 44409 | J21: =J1 -> 44440 | K21: =K1 -> 44470 | L21: =L1 -> 44501 | ... KG21: =KG1 -> 53053
B22: BUDGET | C22: Partial | D22: =BP22 -> 126542.62 | E22: =SUM(E2:E9) -> 82047.934 | F22: =SUM(F2:F9) -> 58123.256 | G22: =SUM(G2:G9) -> 89229.311 | H22: =SUM(H2:H9) -> 83502.398 | I22: =SUM(I2:I9) -> 86506.876 | J22: =SUM(J2:J9) -> 104214.93 | K22: =SUM(K2:K9) -> 89695.165 | L22: =SUM(L2:L9) -> 74887.776 | ... KG22: =SUM(KG2:KG9) -> 44152.58
C23: Cumulative | D23: =BP23 -> 15789655 | E23: =E22 -> 82047.934 | F23: =E23+F22 -> 140171.19 | G23: =F23+G22 -> 229400.5 | H23: =G23+H22 -> 312902.9 | I23: =H23+I22 -> 399409.77 | J23: =I23+J22 -> 503624.7 | K23: =J23+K22 -> 593319.87 | L23: =K23+L22 -> 668207.64 | M23: =L23+M22 -> 742719.93 | ... KG23: =KF23+KG22 -> 52463876
B24: COST | C24: Partial | D24: =BP24 -> 75144.169 | E24: =SUM(E10:E19) -> 33020 | F24: =SUM(F10:F19) -> 100537.86 | G24: =SUM(G10:G19) -> 50827.727 | H24: =SUM(H10:H19) -> 50492.304 | I24: =SUM(I10:I19) -> 95247.454 | J24: =SUM(J10:J19) -> 86602.786 | K24: =SUM(K10:K19) -> 119457.21 | L24: =SUM(L10:L19) -> 82742.376 | ... KG24: =SUM(KG10:KG19) -> 0
C25: Cumulative | D25: =BP25 -> 13344119 | E25: =E24 -> 33020 | F25: =E25+F24 -> 133557.86 | G25: =F25+G24 -> 184385.59 | H25: =G25+H24 -> 234877.89 | I25: =H25+I24 -> 330125.35 | J25: =I25+J24 -> 416728.13 | K25: =J25+K24 -> 536185.35 | L25: =K25+L24 -> 618927.72 | M25: =L25+M24 -> 692450.57 | ... KG25: =KF25+KG24 -> 13344119
B26: BALANCE | C26: Partial | D26: =BP26 -> 51398.452 | E26: =E22-E24 -> 49027.934 | F26: =F22-F24 -> -42414.608 | G26: =G22-G24 -> 38401.584 | H26: =H22-H24 -> 33010.094 | I26: =I22-I24 -> -8740.5779 | J26: =J22-J24 -> 17612.14 | K26: =K22-K24 -> -29762.049 | L26: =L22-L24 -> -7854.6 | ... KG26: =KG22-KG24 -> 44152.58
C27: Cumulative | D27: =BP27 -> 2445536.3 | E27: =E26 -> 49027.934 | F27: =E27+F26 -> 6613.3264 | G27: =F27+G26 -> 45014.91 | H27: =G27+H26 -> 78025.004 | I27: =H27+I26 -> 69284.426 | J27: =I27+J26 -> 86896.566 | K27: =J27+K26 -> 57134.518 | L27: =K27+L26 -> 49279.918 | M27: =L27+M26 -> 50269.364 | ... KG27: =KF27+KG26 -> 39119758
B28: DEVIATION | D28: =BP28 -> 0.15488219 | E28: =E27/E23 -> 0.59755233 | F28: =F27/F23 -> 0.047180354 | G28: =G27/G23 -> 0.19622847 | H28: =H27/H23 -> 0.24935852 | I28: =I27/I23 -> 0.17346703 | J28: =J27/J23 -> 0.1725423 | K28: =K27/K23 -> 0.096296316 | L28: =L27/L23 -> 0.073749407 | ... KG28: =KG27/KG23 -> 0.7456513
D31: JUNE 2026 | E31: =E1 -> 44287 | F31: =F1 -> 44317 | G31: =G1 -> 44348 | H31: =H1 -> 44378 | I31: =I1 -> 44409 | J31: =J1 -> 44440 | K31: =K1 -> 44470 | L31: =L1 -> 44501 | ... BP31: =BP1 -> 46204
B32: INCOME | C32: Received | D32: =BO32 -> 175424 | E32: 163558.79 | F32: 185438.13 | G32: 184615.19 | H32: 231026.67 | I32: 216777.15 | J32: 219744.71 | K32: 220482.32 | L32: 217543.05 | M32: 234143.65 | N32: 259569.13 | O32: 229642.98 | P32: 227604.62 | Q32: 189227.97 | R32: 189968.23 | S32: 174106.41 | T32: 179970.33 | U32: 159287.35 | V32: 114801.05 | W32: 76615.087 | X32: 69817.746 | Y32: 95516.665 | Z32: 120058.77 | AA32: 125043.68 | AB32: 141794.14 | AC32: 187292.87 | AD32: 215588.01 | AE32: 191701.88 | AF32: 170835.27 | AG32: 181884.68 | AH32: 153320.58 | AI32: 174106.31 | AJ32: 204519.07 | AK32: 157652.45 | AL32: 207530.94 | AM32: 175053.42 | AN32: 204465.23 | AO32: 179821.93 | AP32: 191142.78 | AQ32: 170358.49 | AR32: 173996.35 | AS32: 175200.01 | AT32: 157573.15 | AU32: 193730.41 | AV32: 173103.52 | AW32: 195374.77 | AX32: 207026.61 | AY32: 197134.22 | AZ32: 236458.64 | BA32: 184024.81 | BB32: 194580.53 | BC32: 193264.71 | BD32: 167365.69 | BE32: 163120.77 | BF32: 173416.98 | BG32: 189320.7 | BH32: 192997.53 | BI32: 194370.89 | BJ32: 204609.58 | BK32: 197419.78 | BL32: 210056 | BM32: 185303 | BN32: 187799 | BO32: 175424 | BP32: TBD
C33: Accrued | D33: =BO33 -> 190119 | E33: 163694.08 | F33: 185779.82 | G33: 185012.69 | H33: 231257.96 | I33: 217019.03 | J33: 219954.14 | K33: 220714.87 | L33: 218702.4 | M33: 234384.26 | N33: 262400.83 | O33: 236326.29 | P33: 229613.1 | Q33: 191383.74 | R33: 194401.83 | S33: 180662.55 | T33: 185844.67 | U33: 168379.5 | V33: 177424.06 | W33: 188972.25 | X33: 184693.93 | Y33: 203815.52 | Z33: 223035.07 | AA33: 224547.5 | AB33: 197586.93 | AC33: 190470.88 | AD33: 179123.85 | AE33: 161412.97 | AF33: 190755.9 | AG33: 177541.59 | AH33: 209113.2 | AI33: 199950.2 | AJ33: 189698.24 | AK33: 210783.72 | AL33: 252213.39 | AM33: 263820.77 | AN33: 216738.08 | AO33: 207453.71 | AP33: 188914.22 | AQ33: 173379.93 | AR33: 206634.13 | AS33: 193707.23 | AT33: 207593.55 | AU33: 206640.35 | AV33: 203051.57 | AW33: 222615.6 | AX33: 259350.97 | AY33: 267386.56 | AZ33: 231402.25 | BA33: 217040.84 | BB33: 198514.09 | BC33: 197471.86 | BD33: 202730.79 | BE33: 197425.27 | BF33: 205123.42 | BG33: 207446.85 | BH33: 204496.26 | BI33: 228809.91 | BJ33: 259658.4 | BK33: 267614.29 | BL33: 228145 | BM33: 209097 | BN33: 193543 | BO33: 190119 | BP33: TBD
D35: JUNE 2026
B36: ADDITIONAL WORKS | C36: Partial | D36: =BO36 -> 0 | AX36: ='Cost Until 07-26'!AZ59 -> 20000 | AY36: ='Cost Until 07-26'!BA59 -> 0 | AZ36: ='Cost Until 07-26'!BB59 -> 0 | BA36: ='Cost Until 07-26'!BC59 -> 0 | BB36: ='Cost Until 07-26'!BD59 -> 5989 | BC36: ='Cost Until 07-26'!BE59 -> 0 | BD36: ='Cost Until 07-26'!BF59 -> 0 | BE36: ='Cost Until 07-26'!BG59 -> 0 | ... BP36: ='Cost Until 07-26'!BR59 -> 0
C37: Cumulative | D37: =BN37 -> 128716.88 | AX37: =AX36 -> 20000 | AY37: =AX37+AY36 -> 20000 | AZ37: =AY37+AZ36 -> 20000 | BA37: =AZ37+BA36 -> 20000 | BB37: =BA37+BB36 -> 25989 | BC37: =BB37+BC36 -> 25989 | BD37: =BC37+BD36 -> 25989 | BE37: =BD37+BE36 -> 25989 | BF37: =BE37+BF36 -> 25989 | ... BP37: =BO37+BP36 -> 128716.88
A43: MAJOR MAINTENANCE | B43: BUDGET | C43: Partial | E43: =SUM(E4) -> 0 | F43: =SUM(F4) -> 0 | G43: =SUM(G4) -> 0 | H43: =SUM(H4) -> 0 | I43: =SUM(I4) -> 0 | J43: =SUM(J4) -> 0 | K43: =SUM(K4) -> 0 | L43: =SUM(L4) -> 0 | ... BM43: =SUM(BM4) -> 47370
C44: Cumulative | E44: =D44+E43 -> 0 | F44: =E44+F43 -> 0 | G44: =F44+G43 -> 0 | H44: =G44+H43 -> 0 | I44: =H44+I43 -> 0 | J44: =I44+J43 -> 0 | K44: =J44+K43 -> 0 | L44: =K44+L43 -> 0 | ... BM44: =BL44+BM43 -> 1006420.4
B45: COST | C45: Partial | E45: =SUM(E12) -> 0 | F45: =SUM(F12) -> 0 | G45: =SUM(G12) -> 0 | H45: =SUM(H12) -> 0 | I45: =SUM(I12) -> 0 | J45: =SUM(J12) -> 1106 | K45: =SUM(K12) -> 1156 | L45: =SUM(L12) -> 0 | ... BM45: =SUM(BM12) -> 106.94995
C46: Cumulative | E46: =D46+E45 -> 0 | F46: =E46+F45 -> 0 | G46: =F46+G45 -> 0 | H46: =G46+H45 -> 0 | I46: =H46+I45 -> 0 | J46: =I46+J45 -> 1106 | K46: =J46+K45 -> 2262 | L46: =K46+L45 -> 2262 | ... BM46: =BL46+BM45 -> 1027293.2
B47: BALANCE | C47: Partial | E47: =E43-E45 -> 0 | F47: =F43-F45 -> 0 | G47: =G43-G45 -> 0 | H47: =H43-H45 -> 0 | I47: =I43-I45 -> 0 | J47: =J43-J45 -> -1106 | K47: =K43-K45 -> -1156 | L47: =L43-L45 -> 0 | ... BM47: =BM43-BM45 -> 47263.05
C48: Cumulative | E48: =E47 -> 0 | F48: =F47+E48 -> 0 | G48: =G47+F48 -> 0 | H48: =H47+G48 -> 0 | I48: =I47+H48 -> 0 | J48: =J47+I48 -> -1106 | K48: =K47+J48 -> -2262 | L48: =L47+K48 -> -2262 | M48: =M47+L48 -> -2262 | ... BM48: =BM47+BL48 -> -20872.733
B49: DEVIATION | E49: =E48/E44 -> #DIV/0! | F49: =F48/F44 -> #DIV/0! | G49: =G48/G44 -> #DIV/0! | H49: =H48/H44 -> #DIV/0! | I49: =I48/I44 -> #DIV/0! | J49: =J48/J44 -> #DIV/0! | K49: =K48/K44 -> #DIV/0! | L49: =L48/L44 -> #DIV/0! | ... BM49: =BM48/BM44 -> -0.020739576

Sheet Sofia's Query
B1: ITEM | C1: CATEGORY | D1: APR 2026 | E1: =Budget!F1 -> 44287 | F1: =Budget!G1 -> 44317 | G1: =Budget!H1 -> 44348 | H1: =Budget!I1 -> 44378 | I1: =Budget!J1 -> 44409 | J1: =Budget!K1 -> 44440 | K1: =Budget!L1 -> 44470 | L1: =Budget!M1 -> 44501 | ... KG1: =Budget!KH1 -> 53053
A2: BUDGET | B2: EPC | C2: 100 | D2: =SUM(E2:BM2) -> 2646507 | E2: =Balance!E2 -> 0 | F2: =Balance!F2 -> 509.6 | G2: =Balance!G2 -> 30509.6 | H2: =Balance!H2 -> 25742.817 | I2: =Balance!I2 -> 509.6 | J2: =Balance!J2 -> 36384.257 | K2: =Balance!K2 -> 20767.896 | L2: =Balance!L2 -> 9937.2194 | ... KG2: =Balance!KG2 -> 0
B3: ROUTINE MAINTENANCE | C3: 200 | D3: =SUM(E3:BM3) -> 576587.55 | E3: =Balance!E3 -> 0 | F3: =Balance!F3 -> 8500 | G3: =Balance!G3 -> 8500 | H3: =Balance!H3 -> 8500 | I3: =Balance!I3 -> 8500 | J3: =Balance!J3 -> 10751.164 | K3: =Balance!K3 -> 8500 | L3: =Balance!L3 -> 8500 | ... KG3: =Balance!KG3 -> 10000
B4: MAJOR MAINTENANCE | C4: 200 | D4: =SUM(E4:BM4) -> 1006420.4 | E4: =Balance!E4 -> 0 | F4: =Balance!F4 -> 0 | G4: =Balance!G4 -> 0 | H4: =Balance!H4 -> 0 | I4: =Balance!I4 -> 0 | J4: =Balance!J4 -> 0 | K4: =Balance!K4 -> 0 | L4: =Balance!L4 -> 0 | ... KG4: =Balance!KG4 -> 10000
B5: OPERATIONS | C5: 300 | D5: =SUM(E5:BM5) -> 1775113.5 | E5: =Balance!E5 -> 49440.14 | F5: =Balance!F5 -> 20195.524 | G5: =Balance!G5 -> 21139.909 | H5: =Balance!H5 -> 20794.459 | I5: =Balance!I5 -> 28066.484 | J5: =Balance!J5 -> 24242.233 | K5: =Balance!K5 -> 27256.977 | L5: =Balance!L5 -> 22474.925 | ... KG5: =Balance!KG5 -> 24152.58
B6: SPV | C6: 400 | D6: =SUM(E6:BM6) -> 839125.93 | E6: =Balance!E6 -> 4435.7627 | F6: =Balance!F6 -> 6728.0927 | G6: =Balance!G6 -> 6889.7627 | H6: =Balance!H6 -> 6275.0827 | I6: =Balance!I6 -> 27240.753 | J6: =Balance!J6 -> 10647.233 | K6: =Balance!K6 -> 10980.253 | L6: =Balance!L6 -> 11785.593 | ... KG6: =Balance!KG6 -> 0
B7: MOP | C7: 500 | D7: =SUM(E7:BM7) -> 8284097.5 | E7: =Balance!E7 -> 18947.456 | F7: =Balance!F7 -> 18947.456 | G7: =Balance!G7 -> 18947.456 | H7: =Balance!H7 -> 18947.456 | I7: =Balance!I7 -> 18947.456 | J7: =Balance!J7 -> 18947.456 | K7: =Balance!K7 -> 18947.456 | L7: =Balance!L7 -> 18947.456 | ... KG7: =Balance!KG7 -> 0
B8: INSURANCE & GUARANTEE | C8: 700 | D8: =SUM(E8:BM8) -> 205443.6 | E8: =Balance!E8 -> 3242.5833 | F8: =Balance!F8 -> 3242.5833 | G8: =Balance!G8 -> 3242.5833 | H8: =Balance!H8 -> 3242.5833 | I8: =Balance!I8 -> 3242.5833 | J8: =Balance!J8 -> 3242.5833 | K8: =Balance!K8 -> 3242.5833 | L8: =Balance!L8 -> 3242.5833 | ... KG8: =Balance!KG8 -> 0
B9: TAX | C9: 800 | D9: =SUM(E9:BM9) -> 129962.5 | E9: =Balance!E9 -> 5981.9924 | F9: =Balance!F9 -> 0 | G9: =Balance!G9 -> 0 | H9: =Balance!H9 -> 0 | I9: =Balance!I9 -> 0 | J9: =Balance!J9 -> 0 | K9: =Balance!K9 -> 0 | L9: =Balance!L9 -> 0 | ... KG9: =Balance!KG9 -> 0
A10: COST | B10: EPC | C10: 100 | D10: =SUM(E10:BM10) -> 2651925.9 | E10: =Balance!E10 -> 0 | F10: =Balance!F10 -> 34620 | G10: =Balance!G10 -> 1801 | H10: =Balance!H10 -> 10517 | I10: =Balance!I10 -> 27584 | J10: =Balance!J10 -> 19328 | K10: =Balance!K10 -> 13171 | L10: =Balance!L10 -> 6523 | ... KG10: =Balance!KG10 -> 0
B11: ROUTINE MAINTENANCE | C11: 200 | D11: =SUM(E11:BM11) -> 546929 | E11: =Balance!E11 -> 0 | F11: =Balance!F11 -> 1498 | G11: =Balance!G11 -> 261 | H11: =Balance!H11 -> 105 | I11: =Balance!I11 -> 69 | J11: =Balance!J11 -> 492 | K11: =Balance!K11 -> 45901 | L11: =Balance!L11 -> 25500 | ... KG11: =Balance!KG11 -> 0
B12: MAJOR MAINTENANCE | C12: 200 | D12: =SUM(E12:BM12) -> 1027293.2 | E12: =Balance!E12 -> 0 | F12: =Balance!F12 -> 0 | G12: =Balance!G12 -> 0 | H12: =Balance!H12 -> 0 | I12: =Balance!I12 -> 0 | J12: =Balance!J12 -> 1106 | K12: =Balance!K12 -> 1156 | L12: =Balance!L12 -> 0 | ... KG12: =Balance!KG12 -> 0
B13: OPERATIONS | C13: 300 | D13: =SUM(E13:BM13) -> 1734892.5 | E13: =Balance!E13 -> 31312 | F13: =Balance!F13 -> 17724 | G13: =Balance!G13 -> 16577 | H13: =Balance!H13 -> 17453 | I13: =Balance!I13 -> 21441 | J13: =Balance!J13 -> 32810 | K13: =Balance!K13 -> 21600 | L13: =Balance!L13 -> 20279 | ... KG13: =Balance!KG13 -> 0
B14: SPV | C14: 400 | D14: =SUM(E14:BM14) -> 608343.95 | E14: =Balance!E14 -> 760 | F14: =Balance!F14 -> 5027 | G14: =Balance!G14 -> 4700 | H14: =Balance!H14 -> 3416 | I14: =Balance!I14 -> 15672 | J14: =Balance!J14 -> 3729 | K14: =Balance!K14 -> 11017 | L14: =Balance!L14 -> 7959 | ... KG14: =Balance!KG14 -> 0
B15: MOP | C15: 500 | D15: =SUM(E15:BM15) -> 1090422.9 | E15: =Balance!E17 -> 0 | F15: =Balance!F17 -> 16284.864 | G15: =Balance!G17 -> 18467.727 | H15: =Balance!H17 -> 18410.304 | I15: =Balance!I17 -> 23018.454 | J15: =Balance!J17 -> 21517.786 | K15: =Balance!K17 -> 21810.214 | L15: =Balance!L17 -> 21749.376 | ... KG15: =Balance!KG17 -> 0
B16: INSURANCE & GUARANTEE | C16: 700 | D16: =SUM(E16:BM16) -> 202513 | E16: =Balance!E18 -> 948 | F16: =Balance!F18 -> 25300 | G16: =Balance!G18 -> 7582 | H16: =Balance!H18 -> 2 | I16: =Balance!I18 -> 0 | J16: =Balance!J18 -> 0 | K16: =Balance!K18 -> 0 | L16: =Balance!L18 -> 0 | ... KG16: =Balance!KG18 -> 0
B17: TAX | C17: 800 | D17: =SUM(E17:BM17) -> 52531.842 | E17: =Balance!E19 -> 0 | F17: =Balance!F19 -> 84 | G17: =Balance!G19 -> 1439 | H17: =Balance!H19 -> 589 | I17: =Balance!I19 -> 7463 | J17: =Balance!J19 -> 7620 | K17: =Balance!K19 -> 4802 | L17: =Balance!L19 -> 732 | ... KG17: =Balance!KG19 -> 0
B19: EPC | D19: MAY 2026 | E19: =E1 -> 44287 | F19: =F1 -> 44317 | G19: =G1 -> 44348 | H19: =H1 -> 44378 | I19: =I1 -> 44409 | J19: =J1 -> 44440 | K19: =K1 -> 44470 | L19: =L1 -> 44501 | ... KG19: =KG1 -> 53053
B20: BUDGET | C20: Partial | D20: =BN20 -> 38201.27 | E20: =E2 -> 0 | F20: =F2 -> 509.6 | G20: =G2 -> 30509.6 | H20: =H2 -> 25742.817 | I20: =I2 -> 509.6 | J20: =J2 -> 36384.257 | K20: =K2 -> 20767.896 | L20: =L2 -> 9937.2194 | ... KG20: =KG2 -> 0
C21: Cumulative | D21: =BN21 -> 2684708.3 | E21: =E20 -> 0 | F21: =E21+F20 -> 509.6 | G21: =F21+G20 -> 31019.2 | H21: =G21+H20 -> 56762.017 | I21: =H21+I20 -> 57271.617 | J21: =I21+J20 -> 93655.874 | K21: =J21+K20 -> 114423.77 | L21: =K21+L20 -> 124360.99 | M21: =L21+M20 -> 129483.15 | ... KG21: =KF21+KG20 -> 14860182
B22: COST | C22: Partial | D22: =BN22 -> 978 | E22: =E10 -> 0 | F22: =F10 -> 34620 | G22: =G10 -> 1801 | H22: =H10 -> 10517 | I22: =I10 -> 27584 | J22: =J10 -> 19328 | K22: =K10 -> 13171 | L22: =L10 -> 6523 | ... KG22: =KG10 -> 0
C23: Cumulative | D23: =BN23 -> 2652903.9 | E23: =E22 -> 0 | F23: =E23+F22 -> 34620 | G23: =F23+G22 -> 36421 | H23: =G23+H22 -> 46938 | I23: =H23+I22 -> 74522 | J23: =I23+J22 -> 93850 | K23: =J23+K22 -> 107021 | L23: =K23+L22 -> 113544 | M23: =L23+M22 -> 118915 | ... KG23: =KF23+KG22 -> 2655427.5
B24: BALANCE | C24: Partial | D24: =BN24 -> 37223.27 | E24: =E20-E22 -> 0 | F24: =F20-F22 -> -34110.4 | G24: =G20-G22 -> 28708.6 | H24: =H20-H22 -> 15225.817 | I24: =I20-I22 -> -27074.4 | J24: =J20-J22 -> 17056.257 | K24: =K20-K22 -> 7596.8964 | L24: =L20-L22 -> 3414.2194 | ... KG24: =KG20-KG22 -> 0
C25: Cumulative | D25: =BN25 -> 31804.444 | E25: =E24 -> 0 | F25: =E25+F24 -> -34110.4 | G25: =F25+G24 -> -5401.8 | H25: =G25+H24 -> 9824.0168 | I25: =H25+I24 -> -17250.383 | J25: =I25+J24 -> -194.12573 | K25: =J25+K24 -> 7402.7706 | L25: =K25+L24 -> 10816.99 | M25: =L25+M24 -> 10568.149 | ... KG25: =KF25+KG24 -> 12204755
B26: DEVIATION | D26: =BN26 -> 0.011846518 | E26: =E25/E21 -> #DIV/0! | F26: =F25/F21 -> -66.935636 | G26: =G25/G21 -> -0.17414376 | H26: =H25/H21 -> 0.17307378 | I26: =I25/I21 -> -0.30120301 | J26: =J25/J21 -> -0.0020727555 | K26: =K25/K21 -> 0.064696091 | L26: =L25/L21 -> 0.086980572 | ... KG26: =KG25/KG21 -> 0.82130586
B29: ROUTINE MAINTENANCE | D29: MAY 2026 | E29: =E19 -> 44287 | F29: =F19 -> 44317 | G29: =G19 -> 44348 | H29: =H19 -> 44378 | I29: =I19 -> 44409 | J29: =J19 -> 44440 | K29: =K19 -> 44470 | L29: =L19 -> 44501 | ... KG29: =KG19 -> 53053
B30: BUDGET | C30: Partial | D30: =BN30 -> 10000 | E30: =E3 -> 0 | F30: =F3 -> 8500 | G30: =G3 -> 8500 | H30: =H3 -> 8500 | I30: =I3 -> 8500 | J30: =J3 -> 10751.164 | K30: =K3 -> 8500 | L30: =L3 -> 8500 | ... KG30: =KG3 -> 10000
C31: Cumulative | D31: =BN31 -> 586587.55 | E31: =E30 -> 0 | F31: =E31+F30 -> 8500 | G31: =F31+G30 -> 17000 | H31: =G31+H30 -> 25500 | I31: =H31+I30 -> 34000 | J31: =I31+J30 -> 44751.164 | K31: =J31+K30 -> 53251.164 | L31: =K31+L30 -> 61751.164 | M31: =L31+M30 -> 70251.164 | ... KG31: =KF31+KG30 -> 3022769.5
B32: COST | C32: Partial | D32: =BN32 -> 10000 | E32: =E11 -> 0 | F32: =F11 -> 1498 | G32: =G11 -> 261 | H32: =H11 -> 105 | I32: =I11 -> 69 | J32: =J11 -> 492 | K32: =K11 -> 45901 | L32: =L11 -> 25500 | ... KG32: =KG11 -> 0
C33: Cumulative | D33: =BN33 -> 556929 | E33: =E32 -> 0 | F33: =E33+F32 -> 1498 | G33: =F33+G32 -> 1759 | H33: =G33+H32 -> 1864 | I33: =H33+I32 -> 1933 | J33: =I33+J32 -> 2425 | K33: =J33+K32 -> 48326 | L33: =K33+L32 -> 73826 | M33: =L33+M32 -> 90819 | ... KG33: =KF33+KG32 -> 576929
B34: BALANCE | C34: Partial | D34: =BN34 -> 0 | E34: =E30-E32 -> 0 | F34: =F30-F32 -> 7002 | G34: =G30-G32 -> 8239 | H34: =H30-H32 -> 8395 | I34: =I30-I32 -> 8431 | J34: =J30-J32 -> 10259.164 | K34: =K30-K32 -> -37401 | L34: =L30-L32 -> -17000 | ... KG34: =KG30-KG32 -> 10000
C35: Cumulative | D35: =BN35 -> 29658.545 | E35: =E34 -> 0 | F35: =E35+F34 -> 7002 | G35: =F35+G34 -> 15241 | H35: =G35+H34 -> 23636 | I35: =H35+I34 -> 32067 | J35: =I35+J34 -> 42326.164 | K35: =J35+K34 -> 4925.1639 | L35: =K35+L34 -> -12074.836 | M35: =L35+M34 -> -20567.836 | ... KG35: =KF35+KG34 -> 2445840.5
B36: DEVIATION | D36: =BN36 -> 0.050561158 | E36: =E35/E31 -> #DIV/0! | F36: =F35/F31 -> 0.82376471 | G36: =G35/G31 -> 0.89652941 | H36: =H35/H31 -> 0.92690196 | I36: =I35/I31 -> 0.94314706 | J36: =J35/J31 -> 0.94581147 | K36: =K35/K31 -> 0.092489319 | L36: =L35/L31 -> -0.19554022 | ... KG36: =KG35/KG31 -> 0.80913894
B39: MAJOR MAINTENANCE | D39: MAY 2026 | E39: =E29 -> 44287 | F39: =F29 -> 44317 | G39: =G29 -> 44348 | H39: =H29 -> 44378 | I39: =I29 -> 44409 | J39: =J29 -> 44440 | K39: =K29 -> 44470 | L39: =L29 -> 44501 | ... KG39: =KG29 -> 53053
B40: BUDGET | C40: Partial | D40: =BN40 -> 0 | E40: =E4 -> 0 | F40: =F4 -> 0 | G40: =G4 -> 0 | H40: =H4 -> 0 | I40: =I4 -> 0 | J40: =J4 -> 0 | K40: =K4 -> 0 | L40: =L4 -> 0 | ... KG40: =KG4 -> 10000
C41: Cumulative | D41: =BN41 -> 1006420.4 | E41: =E40 -> 0 | F41: =E41+F40 -> 0 | G41: =F41+G40 -> 0 | H41: =G41+H40 -> 0 | I41: =H41+I40 -> 0 | J41: =I41+J40 -> 0 | K41: =J41+K40 -> 0 | L41: =K41+L40 -> 0 | M41: =L41+M40 -> 0 | ... KG41: =KF41+KG40 -> 3612929.9
B42: COST | C42: Partial | D42: =BN42 -> 106.90117 | E42: =E12 -> 0 | F42: =F12 -> 0 | G42: =G12 -> 0 | H42: =H12 -> 0 | I42: =I12 -> 0 | J42: =J12 -> 1106 | K42: =K12 -> 1156 | L42: =L12 -> 0 | ... KG42: =KG12 -> 0
C43: Cumulative | D43: =BN43 -> 1027400.1 | E43: =E42 -> 0 | F43: =E43+F42 -> 0 | G43: =F43+G42 -> 0 | H43: =G43+H42 -> 0 | I43: =H43+I42 -> 0 | J43: =I43+J42 -> 1106 | K43: =J43+K42 -> 2262 | L43: =K43+L42 -> 2262 | M43: =L43+M42 -> 2262 | ... KG43: =KF43+KG42 -> 1043357.8
B44: BALANCE | C44: Partial | D44: =BN44 -> -106.90117 | E44: =E40-E42 -> 0 | F44: =F40-F42 -> 0 | G44: =G40-G42 -> 0 | H44: =H40-H42 -> 0 | I44: =I40-I42 -> 0 | J44: =J40-J42 -> -1106 | K44: =K40-K42 -> -1156 | L44: =L40-L42 -> 0 | ... KG44: =KG40-KG42 -> 10000
C45: Cumulative | D45: =BN45 -> -20979.634 | E45: =E44 -> 0 | F45: =E45+F44 -> 0 | G45: =F45+G44 -> 0 | H45: =G45+H44 -> 0 | I45: =H45+I44 -> 0 | J45: =I45+J44 -> -1106 | K45: =J45+K44 -> -2262 | L45: =K45+L44 -> -2262 | M45: =L45+M44 -> -2262 | ... KG45: =KF45+KG44 -> 2569572.2
...

Sheet Balance by Area
B1: ITEM | C1: CATEGORY | D1: APR 2026 | E1: =Budget!F1 -> 44287 | F1: =Budget!G1 -> 44317 | G1: =Budget!H1 -> 44348 | H1: =Budget!I1 -> 44378 | I1: =Budget!J1 -> 44409 | J1: =Budget!K1 -> 44440 | K1: =Budget!L1 -> 44470 | L1: =Budget!M1 -> 44501 | ... KG1: =Budget!KH1 -> 53053
A2: BUDGET | B2: EPC | C2: 100 | D2: =SUM(E2:BM2) -> 2646507 | E2: =Balance!E2 -> 0 | F2: =Balance!F2 -> 509.6 | G2: =Balance!G2 -> 30509.6 | H2: =Balance!H2 -> 25742.817 | I2: =Balance!I2 -> 509.6 | J2: =Balance!J2 -> 36384.257 | K2: =Balance!K2 -> 20767.896 | L2: =Balance!L2 -> 9937.2194 | ... KG2: =Balance!KG2 -> 0
B3: ROUTINE MAINTENANCE | C3: 200 | D3: =SUM(E3:BM3) -> 576587.55 | E3: =Balance!E3 -> 0 | F3: =Balance!F3 -> 8500 | G3: =Balance!G3 -> 8500 | H3: =Balance!H3 -> 8500 | I3: =Balance!I3 -> 8500 | J3: =Balance!J3 -> 10751.164 | K3: =Balance!K3 -> 8500 | L3: =Balance!L3 -> 8500 | ... KG3: =Balance!KG3 -> 10000
B4: MAJOR MAINTENANCE | C4: 200 | D4: =SUM(E4:BM4) -> 1006420.4 | E4: =Balance!E4 -> 0 | F4: =Balance!F4 -> 0 | G4: =Balance!G4 -> 0 | H4: =Balance!H4 -> 0 | I4: =Balance!I4 -> 0 | J4: =Balance!J4 -> 0 | K4: =Balance!K4 -> 0 | L4: =Balance!L4 -> 0 | ... KG4: =Balance!KG4 -> 10000
B5: OPERATIONS | C5: 300 | D5: =SUM(E5:BM5) -> 1775113.5 | E5: =Balance!E5 -> 49440.14 | F5: =Balance!F5 -> 20195.524 | G5: =Balance!G5 -> 21139.909 | H5: =Balance!H5 -> 20794.459 | I5: =Balance!I5 -> 28066.484 | J5: =Balance!J5 -> 24242.233 | K5: =Balance!K5 -> 27256.977 | L5: =Balance!L5 -> 22474.925 | ... KG5: =Balance!KG5 -> 24152.58
B6: SPV | C6: 400 | D6: =SUM(E6:BM6) -> 839125.93 | E6: =Balance!E6 -> 4435.7627 | F6: =Balance!F6 -> 6728.0927 | G6: =Balance!G6 -> 6889.7627 | H6: =Balance!H6 -> 6275.0827 | I6: =Balance!I6 -> 27240.753 | J6: =Balance!J6 -> 10647.233 | K6: =Balance!K6 -> 10980.253 | L6: =Balance!L6 -> 11785.593 | ... KG6: =Balance!KG6 -> 0
B7: MOP | C7: 500 | D7: =SUM(E7:BM7) -> 8284097.5 | E7: =Balance!E7 -> 18947.456 | F7: =Balance!F7 -> 18947.456 | G7: =Balance!G7 -> 18947.456 | H7: =Balance!H7 -> 18947.456 | I7: =Balance!I7 -> 18947.456 | J7: =Balance!J7 -> 18947.456 | K7: =Balance!K7 -> 18947.456 | L7: =Balance!L7 -> 18947.456 | ... KG7: =Balance!KG7 -> 0
B8: INSURANCE & GUARANTEE | C8: 700 | D8: =SUM(E8:BM8) -> 205443.6 | E8: =Balance!E8 -> 3242.5833 | F8: =Balance!F8 -> 3242.5833 | G8: =Balance!G8 -> 3242.5833 | H8: =Balance!H8 -> 3242.5833 | I8: =Balance!I8 -> 3242.5833 | J8: =Balance!J8 -> 3242.5833 | K8: =Balance!K8 -> 3242.5833 | L8: =Balance!L8 -> 3242.5833 | ... KG8: =Balance!KG8 -> 0
B9: TAX | C9: 800 | D9: =SUM(E9:BM9) -> 129962.5 | E9: =Balance!E9 -> 5981.9924 | F9: =Balance!F9 -> 0 | G9: =Balance!G9 -> 0 | H9: =Balance!H9 -> 0 | I9: =Balance!I9 -> 0 | J9: =Balance!J9 -> 0 | K9: =Balance!K9 -> 0 | L9: =Balance!L9 -> 0 | ... KG9: =Balance!KG9 -> 0
A10: COST | B10: EPC | C10: 100 | D10: =SUM(E10:BM10) -> 2651925.9 | E10: =Balance!E10 -> 0 | F10: =Balance!F10 -> 34620 | G10: =Balance!G10 -> 1801 | H10: =Balance!H10 -> 10517 | I10: =Balance!I10 -> 27584 | J10: =Balance!J10 -> 19328 | K10: =Balance!K10 -> 13171 | L10: =Balance!L10 -> 6523 | ... KG10: =Balance!KG10 -> 0
B11: ROUTINE MAINTENANCE | C11: 200 | D11: =SUM(E11:BM11) -> 546929 | E11: =Balance!E11 -> 0 | F11: =Balance!F11 -> 1498 | G11: =Balance!G11 -> 261 | H11: =Balance!H11 -> 105 | I11: =Balance!I11 -> 69 | J11: =Balance!J11 -> 492 | K11: =Balance!K11 -> 45901 | L11: =Balance!L11 -> 25500 | ... KG11: =Balance!KG11 -> 0
B12: MAJOR MAINTENANCE | C12: 200 | D12: =SUM(E12:BM12) -> 1027293.2 | E12: =Balance!E12 -> 0 | F12: =Balance!F12 -> 0 | G12: =Balance!G12 -> 0 | H12: =Balance!H12 -> 0 | I12: =Balance!I12 -> 0 | J12: =Balance!J12 -> 1106 | K12: =Balance!K12 -> 1156 | L12: =Balance!L12 -> 0 | ... KG12: =Balance!KG12 -> 0
B13: OPERATIONS | C13: 300 | D13: =SUM(E13:BM13) -> 1734892.5 | E13: =Balance!E13 -> 31312 | F13: =Balance!F13 -> 17724 | G13: =Balance!G13 -> 16577 | H13: =Balance!H13 -> 17453 | I13: =Balance!I13 -> 21441 | J13: =Balance!J13 -> 32810 | K13: =Balance!K13 -> 21600 | L13: =Balance!L13 -> 20279 | ... KG13: =Balance!KG13 -> 0
B14: SPV | C14: 400 | D14: =SUM(E14:BM14) -> 608343.95 | E14: =Balance!E14 -> 760 | F14: =Balance!F14 -> 5027 | G14: =Balance!G14 -> 4700 | H14: =Balance!H14 -> 3416 | I14: =Balance!I14 -> 15672 | J14: =Balance!J14 -> 3729 | K14: =Balance!K14 -> 11017 | L14: =Balance!L14 -> 7959 | ... KG14: =Balance!KG14 -> 0
B15: MOP | C15: 500 | D15: =SUM(E15:BM15) -> 1090422.9 | E15: =Balance!E17 -> 0 | F15: =Balance!F17 -> 16284.864 | G15: =Balance!G17 -> 18467.727 | H15: =Balance!H17 -> 18410.304 | I15: =Balance!I17 -> 23018.454 | J15: =Balance!J17 -> 21517.786 | K15: =Balance!K17 -> 21810.214 | L15: =Balance!L17 -> 21749.376 | ... KG15: =Balance!KG17 -> 0
B16: INSURANCE & GUARANTEE | C16: 700 | D16: =SUM(E16:BM16) -> 202513 | E16: =Balance!E18 -> 948 | F16: =Balance!F18 -> 25300 | G16: =Balance!G18 -> 7582 | H16: =Balance!H18 -> 2 | I16: =Balance!I18 -> 0 | J16: =Balance!J18 -> 0 | K16: =Balance!K18 -> 0 | L16: =Balance!L18 -> 0 | ... KG16: =Balance!KG18 -> 0
B17: TAX | C17: 800 | D17: =SUM(E17:BM17) -> 52531.842 | E17: =Balance!E19 -> 0 | F17: =Balance!F19 -> 84 | G17: =Balance!G19 -> 1439 | H17: =Balance!H19 -> 589 | I17: =Balance!I19 -> 7463 | J17: =Balance!J19 -> 7620 | K17: =Balance!K19 -> 4802 | L17: =Balance!L19 -> 732 | ... KG17: =Balance!KG19 -> 0
B19: EPC | D19: JULY 2026 | E19: =E1 -> 44287 | F19: =F1 -> 44317 | G19: =G1 -> 44348 | H19: =H1 -> 44378 | I19: =I1 -> 44409 | J19: =J1 -> 44440 | K19: =K1 -> 44470 | L19: =L1 -> 44501 | ... KG19: =KG1 -> 53053
B20: BUDGET | C20: Partial | D20: =BP20 -> 43790.547 | E20: =E2 -> 0 | F20: =F2 -> 509.6 | G20: =G2 -> 30509.6 | H20: =H2 -> 25742.817 | I20: =I2 -> 509.6 | J20: =J2 -> 36384.257 | K20: =K2 -> 20767.896 | L20: =L2 -> 9937.2194 | ... KG20: =KG2 -> 0
C21: Cumulative | D21: =BP21 -> 2748292.4 | E21: =E20 -> 0 | F21: =E21+F20 -> 509.6 | G21: =F21+G20 -> 31019.2 | H21: =G21+H20 -> 56762.017 | I21: =H21+I20 -> 57271.617 | J21: =I21+J20 -> 93655.874 | K21: =J21+K20 -> 114423.77 | L21: =K21+L20 -> 124360.99 | M21: =L21+M20 -> 129483.15 | ... KG21: =KF21+KG20 -> 14860182
B22: COST | C22: Partial | D22: =BP22 -> 978 | E22: =E10 -> 0 | F22: =F10 -> 34620 | G22: =G10 -> 1801 | H22: =H10 -> 10517 | I22: =I10 -> 27584 | J22: =J10 -> 19328 | K22: =K10 -> 13171 | L22: =L10 -> 6523 | ... KG22: =KG10 -> 0
C23: Cumulative | D23: =BP23 -> 2655427.5 | E23: =E22 -> 0 | F23: =E23+F22 -> 34620 | G23: =F23+G22 -> 36421 | H23: =G23+H22 -> 46938 | I23: =H23+I22 -> 74522 | J23: =I23+J22 -> 93850 | K23: =J23+K22 -> 107021 | L23: =K23+L22 -> 113544 | M23: =L23+M22 -> 118915 | ... KG23: =KF23+KG22 -> 2655427.5
B24: BALANCE | C24: Partial | D24: =BO24 -> 18247.933 | E24: =E20-E22 -> 0 | F24: =F20-F22 -> -34110.4 | G24: =G20-G22 -> 28708.6 | H24: =H20-H22 -> 15225.817 | I24: =I20-I22 -> -27074.4 | J24: =J20-J22 -> 17056.257 | K24: =K20-K22 -> 7596.8964 | L24: =L20-L22 -> 3414.2194 | ... KG24: =KG20-KG22 -> 0
C25: Cumulative | D25: =BO25 -> 50052.378 | E25: =E24 -> 0 | F25: =E25+F24 -> -34110.4 | G25: =F25+G24 -> -5401.8 | H25: =G25+H24 -> 9824.0168 | I25: =H25+I24 -> -17250.383 | J25: =I25+J24 -> -194.12573 | K25: =J25+K24 -> 7402.7706 | L25: =K25+L24 -> 10816.99 | M25: =L25+M24 -> 10568.149 | ... KG25: =KF25+KG24 -> 12204755
B26: DEVIATION | D26: =BO26 -> 0.01850706 | E26: =E25/E21 -> #DIV/0! | F26: =F25/F21 -> -66.935636 | G26: =G25/G21 -> -0.17414376 | H26: =H25/H21 -> 0.17307378 | I26: =I25/I21 -> -0.30120301 | J26: =J25/J21 -> -0.0020727555 | K26: =K25/K21 -> 0.064696091 | L26: =L25/L21 -> 0.086980572 | ... KG26: =KG25/KG21 -> 0.82130586
B29: ROUTINE MAINTENANCE | D29: JULY 2026 | E29: =E19 -> 44287 | F29: =F19 -> 44317 | G29: =G19 -> 44348 | H29: =H19 -> 44378 | I29: =I19 -> 44409 | J29: =J19 -> 44440 | K29: =K19 -> 44470 | L29: =L19 -> 44501 | ... KG29: =KG19 -> 53053
B30: BUDGET | C30: Partial | D30: =BP30 -> 10000 | E30: =E3 -> 0 | F30: =F3 -> 8500 | G30: =G3 -> 8500 | H30: =H3 -> 8500 | I30: =I3 -> 8500 | J30: =J3 -> 10751.164 | K30: =K3 -> 8500 | L30: =L3 -> 8500 | ... KG30: =KG3 -> 10000
C31: Cumulative | D31: =BP31 -> 606587.55 | E31: =E30 -> 0 | F31: =E31+F30 -> 8500 | G31: =F31+G30 -> 17000 | H31: =G31+H30 -> 25500 | I31: =H31+I30 -> 34000 | J31: =I31+J30 -> 44751.164 | K31: =J31+K30 -> 53251.164 | L31: =K31+L30 -> 61751.164 | M31: =L31+M30 -> 70251.164 | ... KG31: =KF31+KG30 -> 3022769.5
B32: COST | C32: Partial | D32: =BP32 -> 10000 | E32: =E11 -> 0 | F32: =F11 -> 1498 | G32: =G11 -> 261 | H32: =H11 -> 105 | I32: =I11 -> 69 | J32: =J11 -> 492 | K32: =K11 -> 45901 | L32: =L11 -> 25500 | ... KG32: =KG11 -> 0
C33: Cumulative | D33: =BP33 -> 576929 | E33: =E32 -> 0 | F33: =E33+F32 -> 1498 | G33: =F33+G32 -> 1759 | H33: =G33+H32 -> 1864 | I33: =H33+I32 -> 1933 | J33: =I33+J32 -> 2425 | K33: =J33+K32 -> 48326 | L33: =K33+L32 -> 73826 | M33: =L33+M32 -> 90819 | ... KG33: =KF33+KG32 -> 576929
B34: BALANCE | C34: Partial | D34: =BP34 -> 0 | E34: =E30-E32 -> 0 | F34: =F30-F32 -> 7002 | G34: =G30-G32 -> 8239 | H34: =H30-H32 -> 8395 | I34: =I30-I32 -> 8431 | J34: =J30-J32 -> 10259.164 | K34: =K30-K32 -> -37401 | L34: =L30-L32 -> -17000 | ... KG34: =KG30-KG32 -> 10000
C35: Cumulative | D35: =BP35 -> 29658.545 | E35: =E34 -> 0 | F35: =E35+F34 -> 7002 | G35: =F35+G34 -> 15241 | H35: =G35+H34 -> 23636 | I35: =H35+I34 -> 32067 | J35: =I35+J34 -> 42326.164 | K35: =J35+K34 -> 4925.1639 | L35: =K35+L34 -> -12074.836 | M35: =L35+M34 -> -20567.836 | ... KG35: =KF35+KG34 -> 2445840.5
B36: DEVIATION | D36: =BP36 -> 0.048894089 | E36: =E35/E31 -> #DIV/0! | F36: =F35/F31 -> 0.82376471 | G36: =G35/G31 -> 0.89652941 | H36: =H35/H31 -> 0.92690196 | I36: =I35/I31 -> 0.94314706 | J36: =J35/J31 -> 0.94581147 | K36: =K35/K31 -> 0.092489319 | L36: =L35/L31 -> -0.19554022 | ... KG36: =KG35/KG31 -> 0.80913894
B39: MAJOR MAINTENANCE | D39: JULY 2026 | E39: =E29 -> 44287 | F39: =F29 -> 44317 | G39: =G29 -> 44348 | H39: =H29 -> 44378 | I39: =I29 -> 44409 | J39: =J29 -> 44440 | K39: =K29 -> 44470 | L39: =L29 -> 44501 | ... KG39: =KG29 -> 53053
B40: BUDGET | C40: Partial | D40: =BP40 -> 14106 | E40: =E4 -> 0 | F40: =F4 -> 0 | G40: =G4 -> 0 | H40: =H4 -> 0 | I40: =I4 -> 0 | J40: =J4 -> 0 | K40: =K4 -> 0 | L40: =L4 -> 0 | ... KG40: =KG4 -> 10000
C41: Cumulative | D41: =BP41 -> 1020526.4 | E41: =E40 -> 0 | F41: =E41+F40 -> 0 | G41: =F41+G40 -> 0 | H41: =G41+H40 -> 0 | I41: =H41+I40 -> 0 | J41: =I41+J40 -> 0 | K41: =J41+K40 -> 0 | L41: =K41+L40 -> 0 | M41: =L41+M40 -> 0 | ... KG41: =KF41+KG40 -> 3612929.9
B42: COST | C42: Partial | D42: =BP42 -> 14837.194 | E42: =E12 -> 0 | F42: =F12 -> 0 | G42: =G12 -> 0 | H42: =H12 -> 0 | I42: =I12 -> 0 | J42: =J12 -> 1106 | K42: =K12 -> 1156 | L42: =L12 -> 0 | ... KG42: =KG12 -> 0
C43: Cumulative | D43: =BP43 -> 1043357.8 | E43: =E42 -> 0 | F43: =E43+F42 -> 0 | G43: =F43+G42 -> 0 | H43: =G43+H42 -> 0 | I43: =H43+I42 -> 0 | J43: =I43+J42 -> 1106 | K43: =J43+K42 -> 2262 | L43: =K43+L42 -> 2262 | M43: =L43+M42 -> 2262 | ... KG43: =KF43+KG42 -> 1043357.8
B44: BALANCE | C44: Partial | D44: =BP44 -> -731.19431 | E44: =E40-E42 -> 0 | F44: =F40-F42 -> 0 | G44: =G40-G42 -> 0 | H44: =H40-H42 -> 0 | I44: =I40-I42 -> 0 | J44: =J40-J42 -> -1106 | K44: =K40-K42 -> -1156 | L44: =L40-L42 -> 0 | ... KG44: =KG40-KG42 -> 10000
C45: Cumulative | D45: =BP45 -> -22831.36 | E45: =E44 -> 0 | F45: =E45+F44 -> 0 | G45: =F45+G44 -> 0 | H45: =G45+H44 -> 0 | I45: =H45+I44 -> 0 | J45: =I45+J44 -> -1106 | K45: =J45+K44 -> -2262 | L45: =K45+L44 -> -2262 | M45: =L45+M44 -> -2262 | ... KG45: =KF45+KG44 -> 2569572.2
...

Sheet Budget
A1: ITEM_ID | B1: CAT-CN | C1: MAIN_ITEM-CN | D1: CAT-CC | E1: SUBCAT-CC | F1: 44287 | G1: 44317 | H1: 44348 | I1: 44378 | J1: 44409 | K1: 44440 | L1: 44470 | M1: 44501 | N1: 44531 | O1: 44562 | P1: 44593 | Q1: 44621 | R1: 44652 | S1: 44682 | T1: 44713 | U1: 44743 | V1: 44774 | W1: 44805 | X1: 44835 | Y1: 44866 | Z1: 44896 | AA1: 44927 | AB1: 44958 | AC1: 44986 | AD1: 45017 | AE1: 45047 | AF1: 45078 | AG1: 45108 | AH1: 45139 | AI1: 45170 | AJ1: 45200 | AK1: 45231 | AL1: 45261 | AM1: 45292 | AN1: 45323 | AO1: 45352 | AP1: 45383 | AQ1: 45413 | AR1: 45444 | AS1: 45474 | AT1: 45505 | AU1: 45536 | AV1: 45566 | AW1: 45597 | AX1: 45627 | AY1: 45658 | AZ1: 45689 | BA1: 45717 | BB1: 45748 | BC1: 45778 | BD1: 45809 | BE1: 45839 | BF1: 45870 | BG1: 45901 | BH1: 45931 | BI1: 45962 | BJ1: 45992 | BK1: 46023 | BL1: 46054 | BM1: 46082 | BN1: 46113 | BO1: 46143 | BP1: 46174 | BQ1: 46204 | BR1: 46235 | BS1: 46266 | BT1: 46296 | BU1: 46327 | BV1: 46357 | BW1: 46388 | BX1: 46419 | BY1: 46447 | BZ1: 46478 | CA1: 46508 | CB1: 46539 | CC1: 46569 | CD1: 46600 | CE1: 46631 | CF1: 46661 | CG1: 46692 | CH1: 46722 | CI1: 46753 | CJ1: 46784 | CK1: 46813 | CL1: 46844 | CM1: 46874 | CN1: 46905 | CO1: 46935 | CP1: 46966 | CQ1: 46997 | CR1: 47027 | CS1: 47058 | CT1: 47088 | CU1: 47119 | CV1: 47150 | CW1: 47178 | CX1: 47209 | CY1: 47239 | CZ1: 47270 | DA1: 47300 | DB1: 47331 | DC1: 47362 | DD1: 47392 | DE1: 47423 | DF1: 47453 | DG1: 47484 | DH1: 47515 | DI1: 47543 | DJ1: 47574 | DK1: 47604 | DL1: 47635 | DM1: 47665 | DN1: 47696 | DO1: 47727 | DP1: 47757 | DQ1: 47788 | DR1: 47818 | DS1: 47849 | DT1: 47880 | DU1: 47908 | DV1: 47939 | DW1: 47969 | DX1: 48000 | DY1: 48030 | DZ1: 48061 | EA1: 48092 | EB1: 48122 | EC1: 48153 | ED1: 48183 | EE1: 48214 | EF1: 48245 | EG1: 48274 | EH1: 48305 | EI1: 48335 | EJ1: 48366 | EK1: 48396 | EL1: 48427 | EM1: 48458 | EN1: 48488 | EO1: 48519 | EP1: 48549 | EQ1: 48580 | ER1: 48611 | ES1: 48639 | ET1: 48670 | EU1: 48700 | EV1: 48731 | EW1: 48761 | EX1: 48792 | EY1: 48823 | EZ1: 48853 | FA1: 48884 | FB1: 48914 | FC1: 48945 | FD1: 48976 | FE1: 49004 | FF1: 49035 | FG1: 49065 | FH1: 49096 | FI1: 49126 | FJ1: 49157 | FK1: 49188 | FL1: 49218 | FM1: 49249 | FN1: 49279 | FO1: 49310 | FP1: 49341 | FQ1: 49369 | FR1: 49400 | FS1: 49430 | FT1: 49461 | FU1: 49491 | FV1: 49522 | FW1: 49553 | FX1: 49583 | FY1: 49614 | FZ1: 49644 | GA1: 49675 | GB1: 49706 | GC1: 49735 | GD1: 49766 | GE1: 49796 | GF1: 49827 | GG1: 49857 | GH1: 49888 | GI1: 49919 | GJ1: 49949 | GK1: 49980 | GL1: 50010 | GM1: 50041 | GN1: 50072 | GO1: 50100 | GP1: 50131 | GQ1: 50161 | GR1: 50192 | GS1: 50222 | GT1: 50253 | GU1: 50284 | GV1: 50314 | GW1: 50345 | GX1: 50375 | GY1: 50406 | GZ1: 50437 | HA1: 50465 | HB1: 50496 | HC1: 50526 | HD1: 50557 | HE1: 50587 | HF1: 50618 | HG1: 50649 | HH1: 50679 | HI1: 50710 | HJ1: 50740 | HK1: 50771 | HL1: 50802 | HM1: 50830 | HN1: 50861 | HO1: 50891 | HP1: 50922 | HQ1: 50952 | HR1: 50983 | HS1: 51014 | HT1: 51044 | HU1: 51075 | HV1: 51105 | HW1: 51136 | HX1: 51167 | HY1: 51196 | HZ1: 51227 | IA1: 51257 | IB1: 51288 | IC1: 51318 | ID1: 51349 | IE1: 51380 | IF1: 51410 | IG1: 51441 | IH1: 51471 | II1: 51502 | IJ1: 51533 | IK1: 51561 | IL1: 51592 | IM1: 51622 | IN1: 51653 | IO1: 51683 | IP1: 51714 | IQ1: 51745 | IR1: 51775 | IS1: 51806 | IT1: 51836 | IU1: 51867 | IV1: 51898 | IW1: 51926 | IX1: 51957 | IY1: 51987 | IZ1: 52018 | JA1: 52048 | JB1: 52079 | JC1: 52110 | JD1: 52140 | JE1: 52171 | JF1: 52201 | JG1: 52232 | JH1: 52263 | JI1: 52291 | JJ1: 52322 | JK1: 52352 | JL1: 52383 | JM1: 52413 | JN1: 52444 | JO1: 52475 | JP1: 52505 | JQ1: 52536 | JR1: 52566 | JS1: 52597 | JT1: 52628 | JU1: 52657 | JV1: 52688 | JW1: 52718 | JX1: 52749 | JY1: 52779 | JZ1: 52810 | KA1: 52841 | KB1: 52871 | KC1: 52902 | KD1: 52932 | KE1: 52963 | KF1: 52994 | KG1: 53022 | KH1: 53053
A2: 3.1 | B2: SPV | C2: Delegate administration Environmental Assessment, citizen participation and territorial. (ILUFFI) | D2: 100 | E2: 108 | F2: 0 | G2: 509.6 | H2: 509.6 | I2: 532.81685 | J2: 509.6 | K2: 961.57445 | L2: 913.57895 | M2: 913.49071 | N2: 905.35 | O2: 1121.1844 | P2: 914.25056 | Q2: 905.35 | R2: 1013.0527 | S2: 958.17487 | T2: 936.18073 | U2: 906.12821 | V2: 895.82 | W2: 928.74208 | X2: 760.79696 | Y2: 1098.6929 | Z2: 837.08858 | AA2: 837.05346 | AB2: 838.59773 | AC2: 848.96324 | AD2: 850.65423 | AE2: 856.35935 | AF2: 858.6044 | AG2: 850.77064 | AH2: 848.09679 | AI2: 848.95367 | AJ2: 860.13843 | AK2: 719.4013 | AL2: 732.78932 | AM2: 736.04182 | AN2: 738.09819 | AO2: 725.59672 | AP2: 717.72216 | AQ2: 724.67879 | AR2: 721.72327 | AS2: 730.51855 | AT2: 747.97 | AU2: 720.37 | AV2: 718.96 | AW2: 722.28 | AX2: 389 | AY2: 711 | AZ2: 711 | BA2: 711 | BB2: 711 | BC2: 711 | BD2: 711 | BE2: 711 | BF2: 711 | BG2: 711 | BH2: 711 | BI2: 711 | BJ2: 711 | BK2: 711 | BL2: 711 | BM2: 711 | BN2: 711 | BO2: 711 | BP2: 711 | BQ2: 711 | BR2: 711 | BS2: 711 | BT2: 711 | BU2: 711 | BV2: 711 | BW2: 500 | BX2: 500 | BY2: 500 | BZ2: 500 | CA2: 500 | CB2: 500 | CC2: 500 | CD2: 500 | CE2: 500 | CF2: 500 | CG2: 500 | CH2: 500 | CI2: 500 | CJ2: 500 | CK2: 500 | CL2: 500 | CM2: 500 | CN2: 500 | CO2: 500 | CP2: 500 | CQ2: 500 | CR2: 500 | CS2: 500 | CT2: 500 | CU2: 500 | CV2: 500 | CW2: 500 | CX2: 500 | CY2: 500 | CZ2: 500 | DA2: 500 | DB2: 500 | DC2: 500 | DD2: 500 | DE2: 500 | DF2: 500 | DG2: 500 | DH2: 500 | DI2: 500 | DJ2: 500 | DK2: 500 | DL2: 500 | DM2: 500 | DN2: 500 | DO2: 500 | DP2: 500 | DQ2: 500 | DR2: 500 | DS2: 500 | DT2: 500 | DU2: 500 | DV2: 500 | DW2: 500 | DX2: 500 | DY2: 500 | DZ2: 500 | EA2: 500 | EB2: 500 | EC2: 500 | ED2: 500 | EE2: 500 | EF2: 500 | EG2: 500 | EH2: 500 | EI2: 500 | EJ2: 500 | EK2: 500 | EL2: 500 | EM2: 500 | EN2: 500 | EO2: 500 | EP2: 500 | EQ2: 500 | ER2: 500 | ES2: 500 | ET2: 500 | EU2: 500 | EV2: 500 | EW2: 500 | EX2: 500 | EY2: 500 | EZ2: 500 | FA2: 500 | FB2: 500 | FC2: 500 | FD2: 500 | FE2: 500 | FF2: 500 | FG2: 500 | FH2: 500 | FI2: 500 | FJ2: 500 | FK2: 500 | FL2: 500 | FM2: 500 | FN2: 500 | FO2: 500 | FP2: 500 | FQ2: 500 | FR2: 500 | FS2: 500 | FT2: 500 | FU2: 500 | FV2: 500 | FW2: 500 | FX2: 500 | FY2: 500 | FZ2: 500 | GA2: 500 | GB2: 500 | GC2: 500 | GD2: 500 | GE2: 500 | GF2: 500 | GG2: 500 | GH2: 500 | GI2: 500 | GJ2: 500 | GK2: 500 | GL2: 500 | GM2: 500 | GN2: 500 | GO2: 500 | GP2: 500 | GQ2: 500 | GR2: 500 | GS2: 500 | GT2: 500 | GU2: 500 | GV2: 500 | GW2: 500 | GX2: 500 | GY2: 500 | GZ2: 500 | HA2: 500 | HB2: 500 | HC2: 500 | HD2: 500 | HE2: 500 | HF2: 500 | HG2: 500 | HH2: 500 | HI2: 500 | HJ2: 500 | HK2: 500 | HL2: 500 | HM2: 500 | HN2: 500 | HO2: 500 | HP2: 500 | HQ2: 500 | HR2: 500 | HS2: 500 | HT2: 500 | HU2: 500 | HV2: 500 | HW2: 500 | HX2: 500 | HY2: 500 | HZ2: 500 | IA2: 500 | IB2: 500 | IC2: 500 | ID2: 500 | IE2: 500 | IF2: 500 | IG2: 500 | IH2: 500 | II2: 500 | IJ2: 500 | IK2: 500 | IL2: 500 | IM2: 500 | IN2: 500 | IO2: 500 | IP2: 500 | IQ2: 500 | IR2: 500 | IS2: 500 | IT2: 500 | IU2: 500 | IV2: 500 | IW2: 500 | IX2: 500 | IY2: 500 | IZ2: 500 | JA2: 500 | JB2: 500 | JC2: 500 | JD2: 500 | JE2: 500 | JF2: 500 | JG2: 500 | JH2: 500 | JI2: 500 | JJ2: 500 | JK2: 500 | JL2: 500 | JM2: 500 | JN2: 500 | JO2: 500 | JP2: 500 | JQ2: 500 | JR2: 500 | JS2: 500 | JT2: 500 | JU2: 500 | JV2: 500 | JW2: 500 | JX2: 500 | JY2: 500 | JZ2: 500 | KA2: 500 | KB2: 500 | KC2: 500 | KD2: 500 | KE2: 500 | KF2: 500 | KG2: 500 | KH2: 0
A3: 3.2 | B3: SPV | C3: Advice on crossings, parallelism, access and the like. (ROBLE) | D3: 100 | E3: 110 | F3: 0 | G3: 0 | H3: 0 | I3: 0 | J3: 0 | K3: 116.91968 | L3: 116.32401 | M3: 115.20536 | N3: 113.77378 | O3: 112.93332 | P3: 112.13402 | Q3: 110.97301 | R3: 110.31356 | S3: 108.77507 | T3: 107.10065 | U3: 105.78227 | V3: 104.73629 | W3: 103.43856 | X3: 102.16523 | Y3: 101.15505 | Z3: 100.54062 | AA3: 99.683917 | AB3: 99.185264 | AC3: 98.564673 | AD3: 98.382369 | AE3: 97.660201 | AF3: 97.13348 | AG3: 96.98117 | AH3: 97.089937 | AI3: 0 | AJ3: 0 | AK3: 265.29 | AL3: 0 | AM3: 0 | AN3: 176.86 | AO3: 0 | AP3: 0 | AQ3: 176.86 | AR3: 176.86 | AS3: 88.43 | AT3: 0 | AU3: 0 | AV3: 0 | AW3: 0 | AX3: 7.8894958 | AY3: 743.72727 | AZ3: 265.68508 | BA3: 265.68508 | BB3: 265.68508 | BC3: 88.3 | BD3: 88.3 | BE3: 88.3 | BF3: 88.3 | BG3: 88.3 | BH3: 88.3 | BI3: 88.3 | BJ3: 88.3 | BK3: 88.3 | BL3: 88.3 | BM3: 88.3 | BN3: 88.3 | BO3: 88.3 | BP3: 88.3 | BQ3: 88.3 | BR3: 88.3 | BS3: 88.3 | BT3: 88.3 | BU3: 88.3 | BV3: 88.3 | BW3: 88.3 | BX3: 88.3 | BY3: 88.3 | BZ3: 88.3 | CA3: 88.3 | CB3: 88.3 | CC3: 88.3 | CD3: 8088.3 | CE3: 88.3 | CF3: 88.3 | CG3: 88.3 | CH3: 2288.3 | CI3: 88.3 | CJ3: 88.3 | CK3: 88.3 | CL3: 88.3 | CM3: 88.3 | CN3: 88.3 | CO3: 88.3 | CP3: 88.3 | CQ3: 88.3 | CR3: 88.3 | CS3: 88.3 | CT3: 88.3 | CU3: 88.225 | CV3: 88.225 | CW3: 88.225 | CX3: 88.225 | CY3: 88.225 | CZ3: 88.225 | DA3: 88.225 | DB3: 88.225 | DC3: 88.225 | DD3: 88.225 | DE3: 88.225 | DF3: 88.225 | DG3: 88.225 | DH3: 88.225 | DI3: 88.225 | DJ3: 88.225 | DK3: 88.225 | DL3: 88.225 | DM3: 88.225 | DN3: 8088.225 | DO3: 88.225 | DP3: 88.225 | DQ3: 88.225 | DR3: 2288.225 | DS3: 88.225 | DT3: 88.225 | DU3: 88.225 | DV3: 88.225 | DW3: 88.225 | DX3: 88.225 | DY3: 88.225 | DZ3: 88.225 | EA3: 88.225 | EB3: 88.225 | EC3: 88.225 | ED3: 88.225 | EE3: 88.225 | EF3: 88.225 | EG3: 88.225 | EH3: 88.225 | EI3: 88.225 | EJ3: 88.225 | EK3: 88.225 | EL3: 88.225 | EM3: 88.225 | EN3: 88.225 | EO3: 88.225 | EP3: 88.225 | EQ3: 88.225 | ER3: 88.225 | ES3: 88.225 | ET3: 88.225 | EU3: 88.225 | EV3: 88.225 | EW3: 88.225 | EX3: 8088.225 | EY3: 88.225 | EZ3: 88.225 | FA3: 88.225 | FB3: 2288.225 | FC3: 88.225 | FD3: 88.225 | FE3: 88.225 | FF3: 88.225 | FG3: 88.225 | FH3: 88.225 | FI3: 88.225 | FJ3: 88.225 | FK3: 88.225 | FL3: 88.225 | FM3: 88.225 | FN3: 88.225 | FO3: 88.225 | FP3: 88.225 | FQ3: 88.225 | FR3: 88.225 | FS3: 88.225 | FT3: 88.225 | FU3: 88.225 | FV3: 88.225 | FW3: 88.225 | FX3: 88.225 | FY3: 88.225 | FZ3: 88.225 | GA3: 88.225 | GB3: 88.225 | GC3: 88.225 | GD3: 88.225 | GE3: 88.225 | GF3: 88.225 | GG3: 88.225 | GH3: 88.225 | GI3: 88.225 | GJ3: 88.225 | GK3: 88.225 | GL3: 88.225 | GM3: 88.225 | GN3: 88.225 | GO3: 88.225 | GP3: 88.225 | GQ3: 88.225 | GR3: 88.225 | GS3: 88.225 | GT3: 88.225 | GU3: 88.225 | GV3: 88.225 | GW3: 88.225 | GX3: 88.225 | GY3: 88.225 | GZ3: 88.225 | HA3: 88.225 | HB3: 88.225 | HC3: 88.225 | HD3: 88.225 | HE3: 88.225 | HF3: 88.225 | HG3: 88.225 | HH3: 88.225 | HI3: 88.225 | HJ3: 88.225 | HK3: 88.225 | HL3: 88.225 | HM3: 88.225 | HN3: 88.225 | HO3: 88.225 | HP3: 88.225 | HQ3: 88.225 | HR3: 88.225 | HS3: 88.225 | HT3: 88.225 | HU3: 88.225 | HV3: 88.225 | HW3: 88.225 | HX3: 88.225 | HY3: 88.225 | HZ3: 88.225 | IA3: 88.225 | IB3: 88.225 | IC3: 88.225 | ID3: 88.225 | IE3: 88.225 | IF3: 88.225 | IG3: 88.225 | IH3: 88.225 | II3: 88.225 | IJ3: 88.225 | IK3: 88.225 | IL3: 88.225 | IM3: 88.225 | IN3: 88.225 | IO3: 88.225 | IP3: 88.225 | IQ3: 88.225 | IR3: 88.225 | IS3: 88.225 | IT3: 88.225 | IU3: 88.225 | IV3: 88.225 | IW3: 88.225 | IX3: 88.225 | IY3: 88.225 | IZ3: 88.225 | JA3: 88.225 | JB3: 88.225 | JC3: 88.225 | JD3: 88.225 | JE3: 88.225 | JF3: 88.225 | JG3: 88.225 | JH3: 88.225 | JI3: 88.225 | JJ3: 88.225 | JK3: 88.225 | JL3: 88.225 | JM3: 88.225 | JN3: 88.225 | JO3: 88.225 | JP3: 88.225 | JQ3: 88.225 | JR3: 88.225 | JS3: 88.225 | JT3: 88.225 | JU3: 88.225 | JV3: 88.225 | JW3: 88.225 | JX3: 88.225 | JY3: 88.225 | JZ3: 88.225 | KA3: 88.225 | KB3: 88.225 | KC3: 88.225 | KD3: 88.225 | KE3: 88.225 | KF3: 88.225 | KG3: 88.225 | KH3: 0
A4: 3.3 | B4: SPV | C4: Pertinence and EIA Lircay Link, Ñuble Bridge and Nebuco Local Road. (AP ECOLOGY) | D4: 100 | E4: 108 | F4: 0 | G4: 0 | H4: 0 | I4: 0 | J4: 0 | K4: 0 | L4: 0 | M4: 0 | N4: 0 | O4: 0 | P4: 0 | Q4: 0 | R4: 0 | S4: 0 | T4: 0 | U4: 0 | V4: 0 | W4: 733.26359 | X4: 0 | Y4: 0 | Z4: 0 | AA4: 351.59106 | AB4: 0 | AC4: 0 | AD4: 0 | AE4: 0 | AF4: 0 | AG4: 0 | AH4: 0 | AI4: 0 | AJ4: 0 | AK4: 0 | AL4: 0 | AM4: 0 | AN4: 0 | AO4: 0 | AP4: 0 | AQ4: 0 | AR4: 0 | AS4: 0 | AT4: 969.60536 | AU4: 0 | AV4: 0 | AW4: 844.04208 | AX4: 0 | AY4: 0 | AZ4: 0 | BA4: 0 | BB4: 0 | BC4: 0 | BD4: 0 | BE4: 0 | BF4: 0 | BG4: 0 | BH4: 0 | BI4: 0 | BJ4: 0 | BK4: 0 | BL4: 0 | BM4: 0 | BN4: 0 | BO4: 0 | BP4: 0 | BQ4: 0 | BR4: 1217.4 | BS4: 0 | BT4: 0 | BU4: 0 | BV4: 0 | BW4: 0 | BX4: 0 | BY4: 0 | BZ4: 0 | CA4: 0 | CB4: 0 | CC4: 0 | CD4: 0 | CE4: 0 | CF4: 0 | CG4: 0 | CH4: 0 | CI4: 0 | CJ4: 0 | CK4: 0 | CL4: 0 | CM4: 0 | CN4: 0 | CO4: 0 | CP4: 0 | CQ4: 0 | CR4: 0 | CS4: 0 | CT4: 0 | CU4: 0 | CV4: 0 | CW4: 0 | CX4: 0 | CY4: 0 | CZ4: 0 | DA4: 0 | DB4: 0 | DC4: 0 | DD4: 0 | DE4: 0 | DF4: 0 | DG4: 0 | DH4: 0 | DI4: 0 | DJ4: 0 | DK4: 0 | DL4: 0 | DM4: 0 | DN4: 0 | DO4: 0 | DP4: 0 | DQ4: 0 | DR4: 0 | DS4: 0 | DT4: 0 | DU4: 0 | DV4: 0 | DW4: 0 | DX4: 0 | DY4: 0 | DZ4: 0 | EA4: 0 | EB4: 0 | EC4: 0 | ED4: 0 | EE4: 0 | EF4: 0 | EG4: 0 | EH4: 0 | EI4: 0 | EJ4: 0 | EK4: 0 | EL4: 0 | EM4: 0 | EN4: 0 | EO4: 0 | EP4: 0 | EQ4: 0 | ER4: 0 | ES4: 0 | ET4: 0 | EU4: 0 | EV4: 0 | EW4: 0 | EX4: 0 | EY4: 0 | EZ4: 0 | FA4: 0 | FB4: 0 | FC4: 0 | FD4: 0 | FE4: 0 | FF4: 0 | FG4: 0 | FH4: 0 | FI4: 0 | FJ4: 0 | FK4: 0 | FL4: 0 | FM4: 0 | FN4: 0 | FO4: 0 | FP4: 0 | FQ4: 0 | FR4: 0 | FS4: 0 | FT4: 0 | FU4: 0 | FV4: 0 | FW4: 0 | FX4: 0 | FY4: 0 | FZ4: 0 | GA4: 0 | GB4: 0 | GC4: 0 | GD4: 0 | GE4: 0 | GF4: 0 | GG4: 0 | GH4: 0 | GI4: 0 | GJ4: 0 | GK4: 0 | GL4: 0 | GM4: 0 | GN4: 0 | GO4: 0 | GP4: 0 | GQ4: 0 | GR4: 0 | GS4: 0 | GT4: 0 | GU4: 0 | GV4: 0 | GW4: 0 | GX4: 0 | GY4: 0 | GZ4: 0 | HA4: 0 | HB4: 0 | HC4: 0 | HD4: 0 | HE4: 0 | HF4: 0 | HG4: 0 | HH4: 0 | HI4: 0 | HJ4: 0 | HK4: 0 | HL4: 0 | HM4: 0 | HN4: 0 | HO4: 0 | HP4: 0 | HQ4: 0 | HR4: 0 | HS4: 0 | HT4: 0 | HU4: 0 | HV4: 0 | HW4: 0 | HX4: 0 | HY4: 0 | HZ4: 0 | IA4: 0 | IB4: 0 | IC4: 0 | ID4: 0 | IE4: 0 | IF4: 0 | IG4: 0 | IH4: 0 | II4: 0 | IJ4: 0 | IK4: 0 | IL4: 0 | IM4: 0 | IN4: 0 | IO4: 0 | IP4: 0 | IQ4: 0 | IR4: 0 | IS4: 0 | IT4: 0 | IU4: 0 | IV4: 0 | IW4: 0 | IX4: 0 | IY4: 0 | IZ4: 0 | JA4: 0 | JB4: 0 | JC4: 0 | JD4: 0 | JE4: 0 | JF4: 0 | JG4: 0 | JH4: 0 | JI4: 0 | JJ4: 0 | JK4: 0 | JL4: 0 | JM4: 0 | JN4: 0 | JO4: 0 | JP4: 0 | JQ4: 0 | JR4: 0 | JS4: 0 | JT4: 0 | JU4: 0 | JV4: 0 | JW4: 0 | JX4: 0 | JY4: 0 | JZ4: 0 | KA4: 0 | KB4: 0 | KC4: 0 | KD4: 0 | KE4: 0 | KF4: 0 | KG4: 0 | KH4: 0
